Workbook

Sheet Trip
A1: Trip Costing — Kunj - Sri Lanka
A2: Yellow cells with blue text are inputs. Everything else is calculated — don't type over it.
D3: Exchange rates
A4: Trip name | B4: Kunj - Sri Lanka | D4: Currency | E4: ₹ per 1 unit | F4: Note
A5: Client | B5: Kunj | D5: INR | E5: 1
A6: Destination | B6: Sri Lanka | D6: USD | E6: 94.3 | F6: Bank / supplier ROE used for this trip
A7: Travel dates | B7: 19 Dec 2026 – 01 Jan 2027 (14N/15D) | D7: EUR
A8: No. of pax | B8: 9 | D8: GBP
A9: Rooms required | B9: 5 rooms (4 DBL + 1 SGL) | D9: CHF
A10: Costing currency | B10: USD | D10: AED
A11: Default markup % | B11: 0.15 | D11: LKR
A12: GST % | B12: 0.05 | D12: THB
A13: TCS % | B13: 0.02 | D13: SGD
A14: Notes | B14: Galle booked by client on own. | D14: JPY
A17: How this workbook works
A18: 1. Fill in the trip details and today's exchange rates (₹ per 1 unit) above.
A19: 2. Quotes tab: one row per price you receive — hotel, room, meal, source, currency and the amount for ONE room for the WHOLE stay (incl. taxes).
A20: 3. The sheet converts everything to the costing currency, flags ⭐ the cheapest source for each hotel/room/meal and shows the difference vs Booking.com.
A21: 4. Compare tab: every hotel/room with all sources side by side; the best price is highlighted green.
A22: 5. Land tab: transfers, tours, passes, trains, flights, visa — amount + 'Total' or 'Per pax'.
A23: 6. Put Y in the Pkg A / B / C columns for the rows each option uses. The Final tab adds them up with markup, GST and TCS, in the costing currency and in ₹.

Sheet Quotes
A1: Hotel quotes
A2: Amount = price for ONE room for the WHOLE stay, incl. taxes, in the currency quoted. Grey columns are calculated.
L3: Red amount = exchange rate missing on Trip tab
A4: # | B4: City | C4: Check-in | D4: Nights | E4: Hotel | F4: Stars | G4: Room type | H4: Meal | I4: Rooms | J4: Source | K4: Currency | L4: Amount quoted (1 room, whole stay) | M4: Cost / room (costing ccy) | N4: Cost / room / night | O4: Total cost (all rooms) | P4: Free cancel until | Q4: Days left | R4: Status | S4: Booking ref | T4: Label (Base / Upg) | U4: Markup % (blank = default) | V4: Sell / room | W4: Sell total (all rooms) | X4: Best price? | Y4: Booking.com price | Z4: Saving vs Booking.com | AA4: Pkg A | AB4: Pkg B | AC4: Pkg C | AD4: Notes
A5: 1 | B5: Negombo | C5: 46375 | D5: 1 | E5: Regal Reseau Hotel And Spa | F5: 4 | G5: Super, Deluxe, King Bed, Sea View 28m2 | H5: BB | I5: 1 | J5: Ottila | K5: INR | L5: 14213 | M5: =IF(L5="","",IFERROR(L5*INDEX(Trip!$E$5:$E$14,MATCH(K5,Trip!$D$5:$D$14,0))/INDEX(Trip!$E$5:$E$14,MATCH(Trip!$B$10,Trip!$D$5:$D$14,0)),"")) -> 150.7211 | N5: =IF(OR(M5="",D5=""),"",M5/D5) -> 150.7211 | O5: =IF(M5="","",M5*I5) -> 150.7211 | P5: 46369 | Q5: =IF(ISNUMBER(P5),P5-TODAY(),IF(P5="","",P5)) -> 67 | R5: Quote | V5: =IF(M5="","",M5*(1+IF(U5="",Trip!$B$11,U5))) -> 173.32927 | W5: =IF(V5="","",V5*I5) -> 173.32927 | X5: =IF(OR(M5="",R5="Unavailable"),"",IF(M5=_xlfn.MINIFS($M$5:$M$604,$E$5:$E$604,E5,$G$5:$G$604,G5,$H$5:$H$604,H5,$R$5:$R$604,"<>Unavailable"),"⭐ Cheapest","")) | Y5: =IF(COUNTIFS($E$5:$E$604,E5,$G$5:$G$604,G5,$J$5:$J$604,"Booking.com")=0,"",_xlfn.MINIFS($M$5:$M$604,$E$5:$E$604,E5,$G$5:$G$604,G5,$J$5:$J$604,"Booking.com")) -> 139.14104 | Z5: =IF(OR(Y5="",M5="",J5="Booking.com"),"",Y5-M5) -> -11.580064
A6: 2 | B6: Negombo | C6: 46375 | D6: 1 | E6: Regal Reseau Hotel And Spa | F6: 4 | G6: Super, Deluxe, King Bed, Sea View 28m2 | H6: BB | I6: 1 | J6: Booking.com | K6: INR | L6: 13121 | M6: =IF(L6="","",IFERROR(L6*INDEX(Trip!$E$5:$E$14,MATCH(K6,Trip!$D$5:$D$14,0))/INDEX(Trip!$E$5:$E$14,MATCH(Trip!$B$10,Trip!$D$5:$D$14,0)),"")) -> 139.14104 | N6: =IF(OR(M6="",D6=""),"",M6/D6) -> 139.14104 | O6: =IF(M6="","",M6*I6) -> 139.14104 | P6: 46372 | Q6: =IF(ISNUMBER(P6),P6-TODAY(),IF(P6="","",P6)) -> 70 | R6: Quote | V6: =IF(M6="","",M6*(1+IF(U6="",Trip!$B$11,U6))) -> 160.0122 | W6: =IF(V6="","",V6*I6) -> 160.0122 | X6: =IF(OR(M6="",R6="Unavailable"),"",IF(M6=_xlfn.MINIFS($M$5:$M$604,$E$5:$E$604,E6,$G$5:$G$604,G6,$H$5:$H$604,H6,$R$5:$R$604,"<>Unavailable"),"⭐ Cheapest","")) -> ⭐ Cheapest | Y6: =IF(COUNTIFS($E$5:$E$604,E6,$G$5:$G$604,G6,$J$5:$J$604,"Booking.com")=0,"",_xlfn.MINIFS($M$5:$M$604,$E$5:$E$604,E6,$G$5:$G$604,G6,$J$5:$J$604,"Booking.com")) -> 139.14104 | Z6: =IF(OR(Y6="",M6="",J6="Booking.com"),"",Y6-M6)
A7: 3 | B7: Negombo | C7: 46375 | D7: 1 | E7: Jetwing Sea Hotel | F7: 4 | G7: Standard Double Sea View | H7: BB | I7: 1 | J7: Ottila | K7: INR | L7: 10318 | M7: =IF(L7="","",IFERROR(L7*INDEX(Trip!$E$5:$E$14,MATCH(K7,Trip!$D$5:$D$14,0))/INDEX(Trip!$E$5:$E$14,MATCH(Trip!$B$10,Trip!$D$5:$D$14,0)),"")) -> 109.41676 | N7: =IF(OR(M7="",D7=""),"",M7/D7) -> 109.41676 | O7: =IF(M7="","",M7*I7) -> 109.41676 | P7: 46357 | Q7: =IF(ISNUMBER(P7),P7-TODAY(),IF(P7="","",P7)) -> 55 | R7: Quote | V7: =IF(M7="","",M7*(1+IF(U7="",Trip!$B$11,U7))) -> 125.82927 | W7: =IF(V7="","",V7*I7) -> 125.82927 | X7: =IF(OR(M7="",R7="Unavailable"),"",IF(M7=_xlfn.MINIFS($M$5:$M$604,$E$5:$E$604,E7,$G$5:$G$604,G7,$H$5:$H$604,H7,$R$5:$R$604,"<>Unavailable"),"⭐ Cheapest","")) -> ⭐ Cheapest | Y7: =IF(COUNTIFS($E$5:$E$604,E7,$G$5:$G$604,G7,$J$5:$J$604,"Booking.com")=0,"",_xlfn.MINIFS($M$5:$M$604,$E$5:$E$604,E7,$G$5:$G$604,G7,$J$5:$J$604,"Booking.com")) | Z7: =IF(OR(Y7="",M7="",J7="Booking.com"),"",Y7-M7)
A8: 4 | B8: Negombo | C8: 46375 | D8: 1 | E8: Jetwing Blue | F8: 5 | G8: Deluxe Room | H8: BB | I8: 1 | J8: Ottila | K8: INR | L8: 15158 | M8: =IF(L8="","",IFERROR(L8*INDEX(Trip!$E$5:$E$14,MATCH(K8,Trip!$D$5:$D$14,0))/INDEX(Trip!$E$5:$E$14,MATCH(Trip!$B$10,Trip!$D$5:$D$14,0)),"")) -> 160.74231 | N8: =IF(OR(M8="",D8=""),"",M8/D8) -> 160.74231 | O8: =IF(M8="","",M8*I8) -> 160.74231 | P8: 46348 | Q8: =IF(ISNUMBER(P8),P8-TODAY(),IF(P8="","",P8)) -> 46 | R8: Quote | T8: Base | V8: =IF(M8="","",M8*(1+IF(U8="",Trip!$B$11,U8))) -> 184.85366 | W8: =IF(V8="","",V8*I8) -> 184.85366 | X8: =IF(OR(M8="",R8="Unavailable"),"",IF(M8=_xlfn.MINIFS($M$5:$M$604,$E$5:$E$604,E8,$G$5:$G$604,G8,$H$5:$H$604,H8,$R$5:$R$604,"<>Unavailable"),"⭐ Cheapest","")) -> ⭐ Cheapest | Y8: =IF(COUNTIFS($E$5:$E$604,E8,$G$5:$G$604,G8,$J$5:$J$604,"Booking.com")=0,"",_xlfn.MINIFS($M$5:$M$604,$E$5:$E$604,E8,$G$5:$G$604,G8,$J$5:$J$604,"Booking.com")) -> 179 | Z8: =IF(OR(Y8="",M8="",J8="Booking.com"),"",Y8-M8) -> 18.257688
A9: 5 | B9: Negombo | C9: 46375 | D9: 1 | E9: Jetwing Blue | F9: 5 | G9: Deluxe Room | H9: BB | I9: 1 | J9: Booking.com | K9: USD | L9: 179 | M9: =IF(L9="","",IFERROR(L9*INDEX(Trip!$E$5:$E$14,MATCH(K9,Trip!$D$5:$D$14,0))/INDEX(Trip!$E$5:$E$14,MATCH(Trip!$B$10,Trip!$D$5:$D$14,0)),"")) -> 179 | N9: =IF(OR(M9="",D9=""),"",M9/D9) -> 179 | O9: =IF(M9="","",M9*I9) -> 179 | Q9: =IF(ISNUMBER(P9),P9-TODAY(),IF(P9="","",P9)) | R9: Quote | V9: =IF(M9="","",M9*(1+IF(U9="",Trip!$B$11,U9))) -> 205.85 | W9: =IF(V9="","",V9*I9) -> 205.85 | X9: =IF(OR(M9="",R9="Unavailable"),"",IF(M9=_xlfn.MINIFS($M$5:$M$604,$E$5:$E$604,E9,$G$5:$G$604,G9,$H$5:$H$604,H9,$R$5:$R$604,"<>Unavailable"),"⭐ Cheapest","")) | Y9: =IF(COUNTIFS($E$5:$E$604,E9,$G$5:$G$604,G9,$J$5:$J$604,"Booking.com")=0,"",_xlfn.MINIFS($M$5:$M$604,$E$5:$E$604,E9,$G$5:$G$604,G9,$J$5:$J$604,"Booking.com")) -> 179 | Z9: =IF(OR(Y9="",M9="",J9="Booking.com"),"",Y9-M9)
A10: 6 | B10: Negombo | C10: 46375 | D10: 1 | E10: The Wallawwa | G10: Walawwa Bedrom (1 King Bed) 35sqmr | H10: BB | I10: 1 | J10: Ottila | K10: INR | L10: 50279 | M10: =IF(L10="","",IFERROR(L10*INDEX(Trip!$E$5:$E$14,MATCH(K10,Trip!$D$5:$D$14,0))/INDEX(Trip!$E$5:$E$14,MATCH(Trip!$B$10,Trip!$D$5:$D$14,0)),"")) -> 533.18134 | N10: =IF(OR(M10="",D10=""),"",M10/D10) -> 533.18134 | O10: =IF(M10="","",M10*I10) -> 533.18134 | P10: 46342 | Q10: =IF(ISNUMBER(P10),P10-TODAY(),IF(P10="","",P10)) -> 40 | R10: Quote | V10: =IF(M10="","",M10*(1+IF(U10="",Trip!$B$11,U10))) -> 613.15854 | W10: =IF(V10="","",V10*I10) -> 613.15854 | X10: =IF(OR(M10="",R10="Unavailable"),"",IF(M10=_xlfn.MINIFS($M$5:$M$604,$E$5:$E$604,E10,$G$5:$G$604,G10,$H$5:$H$604,H10,$R$5:$R$604,"<>Unavailable"),"⭐ Cheapest","")) -> ⭐ Cheapest | Y10: =IF(COUNTIFS($E$5:$E$604,E10,$G$5:$G$604,G10,$J$5:$J$604,"Booking.com")=0,"",_xlfn.MINIFS($M$5:$M$604,$E$5:$E$604,E10,$G$5:$G$604,G10,$J$5:$J$604,"Booking.com")) -> 580 | Z10: =IF(OR(Y10="",M10="",J10="Booking.com"),"",Y10-M10) -> 46.818664
A11: 7 | B11: Negombo | C11: 46375 | D11: 1 | E11: The Wallawwa | G11: Walawwa Bedrom (1 King Bed) 35sqmr | H11: BB | I11: 1 | J11: Booking.com | K11: USD | L11: 580 | M11: =IF(L11="","",IFERROR(L11*INDEX(Trip!$E$5:$E$14,MATCH(K11,Trip!$D$5:$D$14,0))/INDEX(Trip!$E$5:$E$14,MATCH(Trip!$B$10,Trip!$D$5:$D$14,0)),"")) -> 580 | N11: =IF(OR(M11="",D11=""),"",M11/D11) -> 580 | O11: =IF(M11="","",M11*I11) -> 580 | Q11: =IF(ISNUMBER(P11),P11-TODAY(),IF(P11="","",P11)) | R11: Quote | V11: =IF(M11="","",M11*(1+IF(U11="",Trip!$B$11,U11))) -> 667 | W11: =IF(V11="","",V11*I11) -> 667 | X11: =IF(OR(M11="",R11="Unavailable"),"",IF(M11=_xlfn.MINIFS($M$5:$M$604,$E$5:$E$604,E11,$G$5:$G$604,G11,$H$5:$H$604,H11,$R$5:$R$604,"<>Unavailable"),"⭐ Cheapest","")) | Y11: =IF(COUNTIFS($E$5:$E$604,E11,$G$5:$G$604,G11,$J$5:$J$604,"Booking.com")=0,"",_xlfn.MINIFS($M$5:$M$604,$E$5:$E$604,E11,$G$5:$G$604,G11,$J$5:$J$604,"Booking.com")) -> 580 | Z11: =IF(OR(Y11="",M11="",J11="Booking.com"),"",Y11-M11)
A12: 8 | B12: Negombo | C12: 46375 | D12: 1 | E12: Wattura Resort And Spa | G12: Suite With River View (1 King Bed) 72sqmt | H12: BB | I12: 1 | J12: Ottila | K12: INR | L12: 22291 | M12: =IF(L12="","",IFERROR(L12*INDEX(Trip!$E$5:$E$14,MATCH(K12,Trip!$D$5:$D$14,0))/INDEX(Trip!$E$5:$E$14,MATCH(Trip!$B$10,Trip!$D$5:$D$14,0)),"")) -> 236.38388 | N12: =IF(OR(M12="",D12=""),"",M12/D12) -> 236.38388 | O12: =IF(M12="","",M12*I12) -> 236.38388 | P12: 46369 | Q12: =IF(ISNUMBER(P12),P12-TODAY(),IF(P12="","",P12)) -> 67 | R12: Quote | V12: =IF(M12="","",M12*(1+IF(U12="",Trip!$B$11,U12))) -> 271.84146 | W12: =IF(V12="","",V12*I12) -> 271.84146 | X12: =IF(OR(M12="",R12="Unavailable"),"",IF(M12=_xlfn.MINIFS($M$5:$M$604,$E$5:$E$604,E12,$G$5:$G$604,G12,$H$5:$H$604,H12,$R$5:$R$604,"<>Unavailable"),"⭐ Cheapest","")) -> ⭐ Cheapest | Y12: =IF(COUNTIFS($E$5:$E$604,E12,$G$5:$G$604,G12,$J$5:$J$604,"Booking.com")=0,"",_xlfn.MINIFS($M$5:$M$604,$E$5:$E$604,E12,$G$5:$G$604,G12,$J$5:$J$604,"Booking.com")) -> 250 | Z12: =IF(OR(Y12="",M12="",J12="Booking.com"),"",Y12-M12) -> 13.616119
A13: 9 | B13: Negombo | C13: 46375 | D13: 1 | E13: Wattura Resort And Spa | G13: Suite With River View (1 King Bed) 72sqmt | H13: BB | I13: 1 | J13: Booking.com | K13: USD | L13: 250 | M13: =IF(L13="","",IFERROR(L13*INDEX(Trip!$E$5:$E$14,MATCH(K13,Trip!$D$5:$D$14,0))/INDEX(Trip!$E$5:$E$14,MATCH(Trip!$B$10,Trip!$D$5:$D$14,0)),"")) -> 250 | N13: =IF(OR(M13="",D13=""),"",M13/D13) -> 250 | O13: =IF(M13="","",M13*I13) -> 250 | Q13: =IF(ISNUMBER(P13),P13-TODAY(),IF(P13="","",P13)) | R13: Quote | V13: =IF(M13="","",M13*(1+IF(U13="",Trip!$B$11,U13))) -> 287.5 | W13: =IF(V13="","",V13*I13) -> 287.5 | X13: =IF(OR(M13="",R13="Unavailable"),"",IF(M13=_xlfn.MINIFS($M$5:$M$604,$E$5:$E$604,E13,$G$5:$G$604,G13,$H$5:$H$604,H13,$R$5:$R$604,"<>Unavailable"),"⭐ Cheapest","")) | Y13: =IF(COUNTIFS($E$5:$E$604,E13,$G$5:$G$604,G13,$J$5:$J$604,"Booking.com")=0,"",_xlfn.MINIFS($M$5:$M$604,$E$5:$E$604,E13,$G$5:$G$604,G13,$J$5:$J$604,"Booking.com")) -> 250 | Z13: =IF(OR(Y13="",M13="",J13="Booking.com"),"",Y13-M13)
A14: 10 | B14: Negombo | C14: 46375 | D14: 1 | E14: Sentido Heritance Negombo | G14: Deluxe King 40sqmt | H14: BB | I14: 2 | J14: Ottila | K14: INR | L14: 17754 | M14: =IF(L14="","",IFERROR(L14*INDEX(Trip!$E$5:$E$14,MATCH(K14,Trip!$D$5:$D$14,0))/INDEX(Trip!$E$5:$E$14,MATCH(Trip!$B$10,Trip!$D$5:$D$14,0)),"")) -> 188.27147 | N14: =IF(OR(M14="",D14=""),"",M14/D14) -> 188.27147 | O14: =IF(M14="","",M14*I14) -> 376.54295 | P14: 46358 | Q14: =IF(ISNUMBER(P14),P14-TODAY(),IF(P14="","",P14)) -> 56 | R14: Blocked | S14: 101-26160290/1 | U14: 0.2588 | V14: =IF(M14="","",M14*(1+IF(U14="",Trip!$B$11,U14))) -> 236.99613 | W14: =IF(V14="","",V14*I14) -> 473.99226 | X14: =IF(OR(M14="",R14="Unavailable"),"",IF(M14=_xlfn.MINIFS($M$5:$M$604,$E$5:$E$604,E14,$G$5:$G$604,G14,$H$5:$H$604,H14,$R$5:$R$604,"<>Unavailable"),"⭐ Cheapest","")) | Y14: =IF(COUNTIFS($E$5:$E$604,E14,$G$5:$G$604,G14,$J$5:$J$604,"Booking.com")=0,"",_xlfn.MINIFS($M$5:$M$604,$E$5:$E$604,E14,$G$5:$G$604,G14,$J$5:$J$604,"Booking.com")) -> 329 | Z14: =IF(OR(Y14="",M14="",J14="Booking.com"),"",Y14-M14) -> 140.72853 | AA14: Y | AB14: Y | AC14: Y
A15: 11 | B15: Negombo | C15: 46375 | D15: 1 | E15: Sentido Heritance Negombo | G15: Deluxe King 40sqmt | H15: BB | I15: 2 | J15: Booking.com | K15: USD | L15: 329 | M15: =IF(L15="","",IFERROR(L15*INDEX(Trip!$E$5:$E$14,MATCH(K15,Trip!$D$5:$D$14,0))/INDEX(Trip!$E$5:$E$14,MATCH(Trip!$B$10,Trip!$D$5:$D$14,0)),"")) -> 329 | N15: =IF(OR(M15="",D15=""),"",M15/D15) -> 329 | O15: =IF(M15="","",M15*I15) -> 658 | Q15: =IF(ISNUMBER(P15),P15-TODAY(),IF(P15="","",P15)) | R15: Quote | V15: =IF(M15="","",M15*(1+IF(U15="",Trip!$B$11,U15))) -> 378.35 | W15: =IF(V15="","",V15*I15) -> 756.7 | X15: =IF(OR(M15="",R15="Unavailable"),"",IF(M15=_xlfn.MINIFS($M$5:$M$604,$E$5:$E$604,E15,$G$5:$G$604,G15,$H$5:$H$604,H15,$R$5:$R$604,"<>Unavailable"),"⭐ Cheapest","")) | Y15: =IF(COUNTIFS($E$5:$E$604,E15,$G$5:$G$604,G15,$J$5:$J$604,"Booking.com")=0,"",_xlfn.MINIFS($M$5:$M$604,$E$5:$E$604,E15,$G$5:$G$604,G15,$J$5:$J$604,"Booking.com")) -> 329 | Z15: =IF(OR(Y15="",M15="",J15="Booking.com"),"",Y15-M15)
A16: 12 | B16: Negombo | C16: 46375 | D16: 1 | E16: Sentido Heritance Negombo | G16: Deluxe King 40sqmt | H16: BB | I16: 1 | J16: Ottila | K16: INR | L16: 17189 | M16: =IF(L16="","",IFERROR(L16*INDEX(Trip!$E$5:$E$14,MATCH(K16,Trip!$D$5:$D$14,0))/INDEX(Trip!$E$5:$E$14,MATCH(Trip!$B$10,Trip!$D$5:$D$14,0)),"")) -> 182.27996 | N16: =IF(OR(M16="",D16=""),"",M16/D16) -> 182.27996 | O16: =IF(M16="","",M16*I16) -> 182.27996 | P16: 46369 | Q16: =IF(ISNUMBER(P16),P16-TODAY(),IF(P16="","",P16)) -> 67 | R16: Blocked | S16: 101-26160603/1 | V16: =IF(M16="","",M16*(1+IF(U16="",Trip!$B$11,U16))) -> 209.62195 | W16: =IF(V16="","",V16*I16) -> 209.62195 | X16: =IF(OR(M16="",R16="Unavailable"),"",IF(M16=_xlfn.MINIFS($M$5:$M$604,$E$5:$E$604,E16,$G$5:$G$604,G16,$H$5:$H$604,H16,$R$5:$R$604,"<>Unavailable"),"⭐ Cheapest","")) -> ⭐ Cheapest | Y16: =IF(COUNTIFS($E$5:$E$604,E16,$G$5:$G$604,G16,$J$5:$J$604,"Booking.com")=0,"",_xlfn.MINIFS($M$5:$M$604,$E$5:$E$604,E16,$G$5:$G$604,G16,$J$5:$J$604,"Booking.com")) -> 329 | Z16: =IF(OR(Y16="",M16="",J16="Booking.com"),"",Y16-M16) -> 146.72004
A17: 13 | B17: Negombo | C17: 46375 | D17: 1 | E17: Jetwing Blue | G17: TWIN DELUXE SEA VIEW( 2 Adults ) 59sqmt | H17: BB | I17: 1 | J17: Ottila | K17: INR | L17: 16050 | M17: =IF(L17="","",IFERROR(L17*INDEX(Trip!$E$5:$E$14,MATCH(K17,Trip!$D$5:$D$14,0))/INDEX(Trip!$E$5:$E$14,MATCH(Trip!$B$10,Trip!$D$5:$D$14,0)),"")) -> 170.20148 | N17: =IF(OR(M17="",D17=""),"",M17/D17) -> 170.20148 | O17: =IF(M17="","",M17*I17) -> 170.20148 | Q17: =IF(ISNUMBER(P17),P17-TODAY(),IF(P17="","",P17)) | R17: Quote | V17: =IF(M17="","",M17*(1+IF(U17="",Trip!$B$11,U17))) -> 195.73171 | W17: =IF(V17="","",V17*I17) -> 195.73171 | X17: =IF(OR(M17="",R17="Unavailable"),"",IF(M17=_xlfn.MINIFS($M$5:$M$604,$E$5:$E$604,E17,$G$5:$G$604,G17,$H$5:$H$604,H17,$R$5:$R$604,"<>Unavailable"),"⭐ Cheapest","")) -> ⭐ Cheapest | Y17: =IF(COUNTIFS($E$5:$E$604,E17,$G$5:$G$604,G17,$J$5:$J$604,"Booking.com")=0,"",_xlfn.MINIFS($M$5:$M$604,$E$5:$E$604,E17,$G$5:$G$604,G17,$J$5:$J$604,"Booking.com")) | Z17: =IF(OR(Y17="",M17="",J17="Booking.com"),"",Y17-M17)
A18: 14 | B18: Dambulla / Sigiriya | C18: 46376 | D18: 2 | E18: Habarana Village By Cinnamon | F18: 4 | G18: Superior Room 30m2 | H18: BB | I18: 1 | J18: Ottila | K18: INR | L18: 25708 | M18: =IF(L18="","",IFERROR(L18*INDEX(Trip!$E$5:$E$14,MATCH(K18,Trip!$D$5:$D$14,0))/INDEX(Trip!$E$5:$E$14,MATCH(Trip!$B$10,Trip!$D$5:$D$14,0)),"")) -> 272.6193 | N18: =IF(OR(M18="",D18=""),"",M18/D18) -> 136.30965 | O18: =IF(M18="","",M18*I18) -> 272.6193 | P18: 46358 | Q18: =IF(ISNUMBER(P18),P18-TODAY(),IF(P18="","",P18)) -> 56 | R18: Quote | T18: Base | V18: =IF(M18="","",M18*(1+IF(U18="",Trip!$B$11,U18))) -> 313.5122 | W18: =IF(V18="","",V18*I18) -> 313.5122 | X18: =IF(OR(M18="",R18="Unavailable"),"",IF(M18=_xlfn.MINIFS($M$5:$M$604,$E$5:$E$604,E18,$G$5:$G$604,G18,$H$5:$H$604,H18,$R$5:$R$604,"<>Unavailable"),"⭐ Cheapest","")) -> ⭐ Cheapest | Y18: =IF(COUNTIFS($E$5:$E$604,E18,$G$5:$G$604,G18,$J$5:$J$604,"Booking.com")=0,"",_xlfn.MINIFS($M$5:$M$604,$E$5:$E$604,E18,$G$5:$G$604,G18,$J$5:$J$604,"Booking.com")) -> 347.40191 | Z18: =IF(OR(Y18="",M18="",J18="Booking.com"),"",Y18-M18) -> 74.782609
A19: 15 | B19: Dambulla / Sigiriya | C19: 46376 | D19: 2 | E19: Habarana Village By Cinnamon | F19: 4 | G19: Superior Room 30m2 | H19: BB | I19: 1 | J19: Booking.com | K19: INR | L19: 32760 | M19: =IF(L19="","",IFERROR(L19*INDEX(Trip!$E$5:$E$14,MATCH(K19,Trip!$D$5:$D$14,0))/INDEX(Trip!$E$5:$E$14,MATCH(Trip!$B$10,Trip!$D$5:$D$14,0)),"")) -> 347.40191 | N19: =IF(OR(M19="",D19=""),"",M19/D19) -> 173.70095 | O19: =IF(M19="","",M19*I19) -> 347.40191 | P19: 46368 | Q19: =IF(ISNUMBER(P19),P19-TODAY(),IF(P19="","",P19)) -> 66 | R19: Quote | V19: =IF(M19="","",M19*(1+IF(U19="",Trip!$B$11,U19))) -> 399.5122 | W19: =IF(V19="","",V19*I19) -> 399.5122 | X19: =IF(OR(M19="",R19="Unavailable"),"",IF(M19=_xlfn.MINIFS($M$5:$M$604,$E$5:$E$604,E19,$G$5:$G$604,G19,$H$5:$H$604,H19,$R$5:$R$604,"<>Unavailable"),"⭐ Cheapest","")) | Y19: =IF(COUNTIFS($E$5:$E$604,E19,$G$5:$G$604,G19,$J$5:$J$604,"Booking.com")=0,"",_xlfn.MINIFS($M$5:$M$604,$E$5:$E$604,E19,$G$5:$G$604,G19,$J$5:$J$604,"Booking.com")) -> 347.40191 | Z19: =IF(OR(Y19="",M19="",J19="Booking.com"),"",Y19-M19)
A20: 16 | B20: Dambulla / Sigiriya | C20: 46376 | D20: 2 | E20: Sigiriya Jungles Resort & Spa | G20: Deluxe room | H20: BB | I20: 1 | J20: Ottila | K20: INR | L20: 39204.2 | M20: =IF(L20="","",IFERROR(L20*INDEX(Trip!$E$5:$E$14,MATCH(K20,Trip!$D$5:$D$14,0))/INDEX(Trip!$E$5:$E$14,MATCH(Trip!$B$10,Trip!$D$5:$D$14,0)),"")) -> 415.73913 | N20: =IF(OR(M20="",D20=""),"",M20/D20) -> 207.86957 | O20: =IF(M20="","",M20*I20) -> 415.73913 | P20: 46365 | Q20: =IF(ISNUMBER(P20),P20-TODAY(),IF(P20="","",P20)) -> 63 | R20: Blocked | S20: 101-26157689/1 | U20: 0.0006 | V20: =IF(M20="","",M20*(1+IF(U20="",Trip!$B$11,U20))) -> 415.98857 | W20: =IF(V20="","",V20*I20) -> 415.98857 | X20: =IF(OR(M20="",R20="Unavailable"),"",IF(M20=_xlfn.MINIFS($M$5:$M$604,$E$5:$E$604,E20,$G$5:$G$604,G20,$H$5:$H$604,H20,$R$5:$R$604,"<>Unavailable"),"⭐ Cheapest","")) -> ⭐ Cheapest | Y20: =IF(COUNTIFS($E$5:$E$604,E20,$G$5:$G$604,G20,$J$5:$J$604,"Booking.com")=0,"",_xlfn.MINIFS($M$5:$M$604,$E$5:$E$604,E20,$G$5:$G$604,G20,$J$5:$J$604,"Booking.com")) | Z20: =IF(OR(Y20="",M20="",J20="Booking.com"),"",Y20-M20) | AA20: Y | AB20: Y | AC20: Y
A21: 17 | B21: Dambulla / Sigiriya | C21: 46376 | D21: 2 | E21: Sigiriya Jungles Resort & Spa | G21: Deluxe room | H21: BB | I21: 1 | J21: Hotel website | K21: USD | L21: 416 | M21: =IF(L21="","",IFERROR(L21*INDEX(Trip!$E$5:$E$14,MATCH(K21,Trip!$D$5:$D$14,0))/INDEX(Trip!$E$5:$E$14,MATCH(Trip!$B$10,Trip!$D$5:$D$14,0)),"")) -> 416 | N21: =IF(OR(M21="",D21=""),"",M21/D21) -> 208 | O21: =IF(M21="","",M21*I21) -> 416 | Q21: =IF(ISNUMBER(P21),P21-TODAY(),IF(P21="","",P21)) | R21: Quote | V21: =IF(M21="","",M21*(1+IF(U21="",Trip!$B$11,U21))) -> 478.4 | W21: =IF(V21="","",V21*I21) -> 478.4 | X21: =IF(OR(M21="",R21="Unavailable"),"",IF(M21=_xlfn.MINIFS($M$5:$M$604,$E$5:$E$604,E21,$G$5:$G$604,G21,$H$5:$H$604,H21,$R$5:$R$604,"<>Unavailable"),"⭐ Cheapest","")) | Y21: =IF(COUNTIFS($E$5:$E$604,E21,$G$5:$G$604,G21,$J$5:$J$604,"Booking.com")=0,"",_xlfn.MINIFS($M$5:$M$604,$E$5:$E$604,E21,$G$5:$G$604,G21,$J$5:$J$604,"Booking.com")) | Z21: =IF(OR(Y21="",M21="",J21="Booking.com"),"",Y21-M21)
A22: 18 | B22: Dambulla / Sigiriya | C22: 46376 | D22: 2 | E22: Cinnamon Lodge -Habarana | F22: 5 | G22: Superior room | H22: HB | I22: 1 | J22: BTR | K22: USD | L22: 340 | M22: =IF(L22="","",IFERROR(L22*INDEX(Trip!$E$5:$E$14,MATCH(K22,Trip!$D$5:$D$14,0))/INDEX(Trip!$E$5:$E$14,MATCH(Trip!$B$10,Trip!$D$5:$D$14,0)),"")) -> 340 | N22: =IF(OR(M22="",D22=""),"",M22/D22) -> 170 | O22: =IF(M22="","",M22*I22) -> 340 | Q22: =IF(ISNUMBER(P22),P22-TODAY(),IF(P22="","",P22)) | R22: Quote | T22: Upg 2 | V22: =IF(M22="","",M22*(1+IF(U22="",Trip!$B$11,U22))) -> 391 | W22: =IF(V22="","",V22*I22) -> 391 | X22: =IF(OR(M22="",R22="Unavailable"),"",IF(M22=_xlfn.MINIFS($M$5:$M$604,$E$5:$E$604,E22,$G$5:$G$604,G22,$H$5:$H$604,H22,$R$5:$R$604,"<>Unavailable"),"⭐ Cheapest","")) -> ⭐ Cheapest | Y22: =IF(COUNTIFS($E$5:$E$604,E22,$G$5:$G$604,G22,$J$5:$J$604,"Booking.com")=0,"",_xlfn.MINIFS($M$5:$M$604,$E$5:$E$604,E22,$G$5:$G$604,G22,$J$5:$J$604,"Booking.com")) -> 438.17603 | Z22: =IF(OR(Y22="",M22="",J22="Booking.com"),"",Y22-M22) -> 98.176034
A23: 19 | B23: Dambulla / Sigiriya | C23: 46376 | D23: 2 | E23: Cinnamon Lodge -Habarana | F23: 5 | G23: Superior room | H23: HB | I23: 1 | J23: Booking.com | K23: INR | L23: 41320 | M23: =IF(L23="","",IFERROR(L23*INDEX(Trip!$E$5:$E$14,MATCH(K23,Trip!$D$5:$D$14,0))/INDEX(Trip!$E$5:$E$14,MATCH(Trip!$B$10,Trip!$D$5:$D$14,0)),"")) -> 438.17603 | N23: =IF(OR(M23="",D23=""),"",M23/D23) -> 219.08802 | O23: =IF(M23="","",M23*I23) -> 438.17603 | P23: 46368 | Q23: =IF(ISNUMBER(P23),P23-TODAY(),IF(P23="","",P23)) -> 66 | R23: Quote | V23: =IF(M23="","",M23*(1+IF(U23="",Trip!$B$11,U23))) -> 503.90244 | W23: =IF(V23="","",V23*I23) -> 503.90244 | X23: =IF(OR(M23="",R23="Unavailable"),"",IF(M23=_xlfn.MINIFS($M$5:$M$604,$E$5:$E$604,E23,$G$5:$G$604,G23,$H$5:$H$604,H23,$R$5:$R$604,"<>Unavailable"),"⭐ Cheapest","")) | Y23: =IF(COUNTIFS($E$5:$E$604,E23,$G$5:$G$604,G23,$J$5:$J$604,"Booking.com")=0,"",_xlfn.MINIFS($M$5:$M$604,$E$5:$E$604,E23,$G$5:$G$604,G23,$J$5:$J$604,"Booking.com")) -> 438.17603 | Z23: =IF(OR(Y23="",M23="",J23="Booking.com"),"",Y23-M23)
A24: 20 | B24: Dambulla / Sigiriya | C24: 46376 | D24: 2 | E24: EKHO Sigiriya | G24: Deluxe Room 22 SQM | H24: BB | I24: 1 | J24: Ottila | K24: INR | L24: 26817 | M24: =IF(L24="","",IFERROR(L24*INDEX(Trip!$E$5:$E$14,MATCH(K24,Trip!$D$5:$D$14,0))/INDEX(Trip!$E$5:$E$14,MATCH(Trip!$B$10,Trip!$D$5:$D$14,0)),"")) -> 284.37964 | N24: =IF(OR(M24="",D24=""),"",M24/D24) -> 142.18982 | O24: =IF(M24="","",M24*I24) -> 284.37964 | P24: 46362 | Q24: =IF(ISNUMBER(P24),P24-TODAY(),IF(P24="","",P24)) -> 60 | R24: Quote | T24: Upg 3 | V24: =IF(M24="","",M24*(1+IF(U24="",Trip!$B$11,U24))) -> 327.03659 | W24: =IF(V24="","",V24*I24) -> 327.03659 | X24: =IF(OR(M24="",R24="Unavailable"),"",IF(M24=_xlfn.MINIFS($M$5:$M$604,$E$5:$E$604,E24,$G$5:$G$604,G24,$H$5:$H$604,H24,$R$5:$R$604,"<>Unavailable"),"⭐ Cheapest","")) -> ⭐ Cheapest | Y24: =IF(COUNTIFS($E$5:$E$604,E24,$G$5:$G$604,G24,$J$5:$J$604,"Booking.com")=0,"",_xlfn.MINIFS($M$5:$M$604,$E$5:$E$604,E24,$G$5:$G$604,G24,$J$5:$J$604,"Booking.com")) | Z24: =IF(OR(Y24="",M24="",J24="Booking.com"),"",Y24-M24)
A25: 21 | B25: Dambulla / Sigiriya | C25: 46376 | D25: 2 | E25: EKHO Sigiriya | G25: suite room | H25: HB | I25: 1 | J25: Direct | K25: INR | L25: 49108 | M25: =IF(L25="","",IFERROR(L25*INDEX(Trip!$E$5:$E$14,MATCH(K25,Trip!$D$5:$D$14,0))/INDEX(Trip!$E$5:$E$14,MATCH(Trip!$B$10,Trip!$D$5:$D$14,0)),"")) -> 520.76352 | N25: =IF(OR(M25="",D25=""),"",M25/D25) -> 260.38176 | O25: =IF(M25="","",M25*I25) -> 520.76352 | P25: 46372 | Q25: =IF(ISNUMBER(P25),P25-TODAY(),IF(P25="","",P25)) -> 70 | R25: Quote | V25: =IF(M25="","",M25*(1+IF(U25="",Trip!$B$11,U25))) -> 598.87805 | W25: =IF(V25="","",V25*I25) -> 598.87805 | X25: =IF(OR(M25="",R25="Unavailable"),"",IF(M25=_xlfn.MINIFS($M$5:$M$604,$E$5:$E$604,E25,$G$5:$G$604,G25,$H$5:$H$604,H25,$R$5:$R$604,"<>Unavailable"),"⭐ Cheapest","")) -> ⭐ Cheapest | Y25: =IF(COUNTIFS($E$5:$E$604,E25,$G$5:$G$604,G25,$J$5:$J$604,"Booking.com")=0,"",_xlfn.MINIFS($M$5:$M$604,$E$5:$E$604,E25,$G$5:$G$604,G25,$J$5:$J$604,"Booking.com")) | Z25: =IF(OR(Y25="",M25="",J25="Booking.com"),"",Y25-M25)
A26: 22 | B26: Kandy | C26: 46378 | D26: 1 | E26: Amaya Hills Kandy | G26: Deluxe Room 21-22sqm | H26: BB | I26: 1 | J26: Ottila | K26: INR | L26: 23563 | M26: =IF(L26="","",IFERROR(L26*INDEX(Trip!$E$5:$E$14,MATCH(K26,Trip!$D$5:$D$14,0))/INDEX(Trip!$E$5:$E$14,MATCH(Trip!$B$10,Trip!$D$5:$D$14,0)),"")) -> 249.87275 | N26: =IF(OR(M26="",D26=""),"",M26/D26) -> 249.87275 | O26: =IF(M26="","",M26*I26) -> 249.87275 | P26: 46367 | Q26: =IF(ISNUMBER(P26),P26-TODAY(),IF(P26="","",P26)) -> 65 | R26: Quote | T26: Base | V26: =IF(M26="","",M26*(1+IF(U26="",Trip!$B$11,U26))) -> 287.35366 | W26: =IF(V26="","",V26*I26) -> 287.35366 | X26: =IF(OR(M26="",R26="Unavailable"),"",IF(M26=_xlfn.MINIFS($M$5:$M$604,$E$5:$E$604,E26,$G$5:$G$604,G26,$H$5:$H$604,H26,$R$5:$R$604,"<>Unavailable"),"⭐ Cheapest","")) -> ⭐ Cheapest | Y26: =IF(COUNTIFS($E$5:$E$604,E26,$G$5:$G$604,G26,$J$5:$J$604,"Booking.com")=0,"",_xlfn.MINIFS($M$5:$M$604,$E$5:$E$604,E26,$G$5:$G$604,G26,$J$5:$J$604,"Booking.com")) -> 325 | Z26: =IF(OR(Y26="",M26="",J26="Booking.com"),"",Y26-M26) -> 75.127253
A27: 23 | B27: Kandy | C27: 46378 | D27: 1 | E27: Amaya Hills Kandy | G27: Deluxe Room 21-22sqm | H27: BB | I27: 1 | J27: Booking.com | K27: USD | L27: 325 | M27: =IF(L27="","",IFERROR(L27*INDEX(Trip!$E$5:$E$14,MATCH(K27,Trip!$D$5:$D$14,0))/INDEX(Trip!$E$5:$E$14,MATCH(Trip!$B$10,Trip!$D$5:$D$14,0)),"")) -> 325 | N27: =IF(OR(M27="",D27=""),"",M27/D27) -> 325 | O27: =IF(M27="","",M27*I27) -> 325 | P27: 46370 | Q27: =IF(ISNUMBER(P27),P27-TODAY(),IF(P27="","",P27)) -> 68 | R27: Quote | V27: =IF(M27="","",M27*(1+IF(U27="",Trip!$B$11,U27))) -> 373.75 | W27: =IF(V27="","",V27*I27) -> 373.75 | X27: =IF(OR(M27="",R27="Unavailable"),"",IF(M27=_xlfn.MINIFS($M$5:$M$604,$E$5:$E$604,E27,$G$5:$G$604,G27,$H$5:$H$604,H27,$R$5:$R$604,"<>Unavailable"),"⭐ Cheapest","")) | Y27: =IF(COUNTIFS($E$5:$E$604,E27,$G$5:$G$604,G27,$J$5:$J$604,"Booking.com")=0,"",_xlfn.MINIFS($M$5:$M$604,$E$5:$E$604,E27,$G$5:$G$604,G27,$J$5:$J$604,"Booking.com")) -> 325 | Z27: =IF(OR(Y27="",M27="",J27="Booking.com"),"",Y27-M27)
A28: 24 | B28: Kandy | C28: 46378 | D28: 1 | E28: Santani Wellness Kandy | F28: 5 | G28: Chalet, Garden View DBL | H28: AI | I28: 1 | J28: Ottila | K28: INR | L28: 105906 | M28: =IF(L28="","",IFERROR(L28*INDEX(Trip!$E$5:$E$14,MATCH(K28,Trip!$D$5:$D$14,0))/INDEX(Trip!$E$5:$E$14,MATCH(Trip!$B$10,Trip!$D$5:$D$14,0)),"")) -> 1123.0753 | N28: =IF(OR(M28="",D28=""),"",M28/D28) -> 1123.0753 | O28: =IF(M28="","",M28*I28) -> 1123.0753 | P28: 46345 | Q28: =IF(ISNUMBER(P28),P28-TODAY(),IF(P28="","",P28)) -> 43 | R28: Quote | T28: Upg 3 | V28: =IF(M28="","",M28*(1+IF(U28="",Trip!$B$11,U28))) -> 1291.5366 | W28: =IF(V28="","",V28*I28) -> 1291.5366 | X28: =IF(OR(M28="",R28="Unavailable"),"",IF(M28=_xlfn.MINIFS($M$5:$M$604,$E$5:$E$604,E28,$G$5:$G$604,G28,$H$5:$H$604,H28,$R$5:$R$604,"<>Unavailable"),"⭐ Cheapest","")) -> ⭐ Cheapest | Y28: =IF(COUNTIFS($E$5:$E$604,E28,$G$5:$G$604,G28,$J$5:$J$604,"Booking.com")=0,"",_xlfn.MINIFS($M$5:$M$604,$E$5:$E$604,E28,$G$5:$G$604,G28,$J$5:$J$604,"Booking.com")) | Z28: =IF(OR(Y28="",M28="",J28="Booking.com"),"",Y28-M28)
A29: 25 | B29: Kandy | C29: 46378 | D29: 1 | E29: Santani Wellness Kandy | F29: 5 | G29: Chalet, Garden View SGL | H29: AI | I29: 1 | J29: Ottila | K29: INR | L29: 80156 | M29: =IF(L29="","",IFERROR(L29*INDEX(Trip!$E$5:$E$14,MATCH(K29,Trip!$D$5:$D$14,0))/INDEX(Trip!$E$5:$E$14,MATCH(Trip!$B$10,Trip!$D$5:$D$14,0)),"")) -> 850.0106 | N29: =IF(OR(M29="",D29=""),"",M29/D29) -> 850.0106 | O29: =IF(M29="","",M29*I29) -> 850.0106 | P29: 46345 | Q29: =IF(ISNUMBER(P29),P29-TODAY(),IF(P29="","",P29)) -> 43 | R29: Quote | T29: Upg 3 | V29: =IF(M29="","",M29*(1+IF(U29="",Trip!$B$11,U29))) -> 977.5122 | W29: =IF(V29="","",V29*I29) -> 977.5122 | X29: =IF(OR(M29="",R29="Unavailable"),"",IF(M29=_xlfn.MINIFS($M$5:$M$604,$E$5:$E$604,E29,$G$5:$G$604,G29,$H$5:$H$604,H29,$R$5:$R$604,"<>Unavailable"),"⭐ Cheapest","")) -> ⭐ Cheapest | Y29: =IF(COUNTIFS($E$5:$E$604,E29,$G$5:$G$604,G29,$J$5:$J$604,"Booking.com")=0,"",_xlfn.MINIFS($M$5:$M$604,$E$5:$E$604,E29,$G$5:$G$604,G29,$J$5:$J$604,"Booking.com")) | Z29: =IF(OR(Y29="",M29="",J29="Booking.com"),"",Y29-M29)
A30: 26 | B30: Kandy | C30: 46378 | D30: 1 | E30: W15 Hanthana Estate Kandy | F30: 5 | G30: Deluxe Room, 1 King Bed (1 King Bed) DBL/SGL 30sqm | H30: AI | I30: 1 | J30: Ottila | K30: INR | L30: 171688 | M30: =IF(L30="","",IFERROR(L30*INDEX(Trip!$E$5:$E$14,MATCH(K30,Trip!$D$5:$D$14,0))/INDEX(Trip!$E$5:$E$14,MATCH(Trip!$B$10,Trip!$D$5:$D$14,0)),"")) -> 1820.6575 | N30: =IF(OR(M30="",D30=""),"",M30/D30) -> 1820.6575 | O30: =IF(M30="","",M30*I30) -> 1820.6575 | P30: 46346 | Q30: =IF(ISNUMBER(P30),P30-TODAY(),IF(P30="","",P30)) -> 44 | R30: Quote | T30: Upg 4 | V30: =IF(M30="","",M30*(1+IF(U30="",Trip!$B$11,U30))) -> 2093.7561 | W30: =IF(V30="","",V30*I30) -> 2093.7561 | X30: =IF(OR(M30="",R30="Unavailable"),"",IF(M30=_xlfn.MINIFS($M$5:$M$604,$E$5:$E$604,E30,$G$5:$G$604,G30,$H$5:$H$604,H30,$R$5:$R$604,"<>Unavailable"),"⭐ Cheapest","")) -> ⭐ Cheapest | Y30: =IF(COUNTIFS($E$5:$E$604,E30,$G$5:$G$604,G30,$J$5:$J$604,"Booking.com")=0,"",_xlfn.MINIFS($M$5:$M$604,$E$5:$E$604,E30,$G$5:$G$604,G30,$J$5:$J$604,"Booking.com")) -> 1307.0732 | Z30: =IF(OR(Y30="",M30="",J30="Booking.com"),"",Y30-M30) -> -513.58431
A31: 27 | B31: Kandy | C31: 46378 | D31: 1 | E31: W15 Hanthana Estate Kandy | F31: 5 | G31: Deluxe Room, 1 King Bed (1 King Bed) DBL/SGL 30sqm | H31: BB | I31: 1 | J31: Booking.com | K31: INR | L31: 123257 | M31: =IF(L31="","",IFERROR(L31*INDEX(Trip!$E$5:$E$14,MATCH(K31,Trip!$D$5:$D$14,0))/INDEX(Trip!$E$5:$E$14,MATCH(Trip!$B$10,Trip!$D$5:$D$14,0)),"")) -> 1307.0732 | N31: =IF(OR(M31="",D31=""),"",M31/D31) -> 1307.0732 | O31: =IF(M31="","",M31*I31) -> 1307.0732 | P31: 46347 | Q31: =IF(ISNUMBER(P31),P31-TODAY(),IF(P31="","",P31)) -> 45 | R31: Quote | V31: =IF(M31="","",M31*(1+IF(U31="",Trip!$B$11,U31))) -> 1503.1341 | W31: =IF(V31="","",V31*I31) -> 1503.1341 | X31: =IF(OR(M31="",R31="Unavailable"),"",IF(M31=_xlfn.MINIFS($M$5:$M$604,$E$5:$E$604,E31,$G$5:$G$604,G31,$H$5:$H$604,H31,$R$5:$R$604,"<>Unavailable"),"⭐ Cheapest","")) -> ⭐ Cheapest | Y31: =IF(COUNTIFS($E$5:$E$604,E31,$G$5:$G$604,G31,$J$5:$J$604,"Booking.com")=0,"",_xlfn.MINIFS($M$5:$M$604,$E$5:$E$604,E31,$G$5:$G$604,G31,$J$5:$J$604,"Booking.com")) -> 1307.0732 | Z31: =IF(OR(Y31="",M31="",J31="Booking.com"),"",Y31-M31)
A32: 28 | B32: Kandy | C32: 46378 | D32: 1 | E32: Taru Villas | G32: Deluxe Room DBL/SGL 27sqm | H32: BB | I32: 1 | J32: Ottila | K32: INR | L32: 40298 | M32: =IF(L32="","",IFERROR(L32*INDEX(Trip!$E$5:$E$14,MATCH(K32,Trip!$D$5:$D$14,0))/INDEX(Trip!$E$5:$E$14,MATCH(Trip!$B$10,Trip!$D$5:$D$14,0)),"")) -> 427.33828 | N32: =IF(OR(M32="",D32=""),"",M32/D32) -> 427.33828 | O32: =IF(M32="","",M32*I32) -> 427.33828 | P32: 46314 | Q32: =IF(ISNUMBER(P32),P32-TODAY(),IF(P32="","",P32)) -> 12 | R32: Quote | V32: =IF(M32="","",M32*(1+IF(U32="",Trip!$B$11,U32))) -> 491.43902 | W32: =IF(V32="","",V32*I32) -> 491.43902 | X32: =IF(OR(M32="",R32="Unavailable"),"",IF(M32=_xlfn.MINIFS($M$5:$M$604,$E$5:$E$604,E32,$G$5:$G$604,G32,$H$5:$H$604,H32,$R$5:$R$604,"<>Unavailable"),"⭐ Cheapest","")) -> ⭐ Cheapest | Y32: =IF(COUNTIFS($E$5:$E$604,E32,$G$5:$G$604,G32,$J$5:$J$604,"Booking.com")=0,"",_xlfn.MINIFS($M$5:$M$604,$E$5:$E$604,E32,$G$5:$G$604,G32,$J$5:$J$604,"Booking.com")) -> 368.8017 | Z32: =IF(OR(Y32="",M32="",J32="Booking.com"),"",Y32-M32) -> -58.536585
A33: 29 | B33: Kandy | C33: 46378 | D33: 1 | E33: Taru Villas | G33: Deluxe Room DBL/SGL 27sqm | H33: HB | I33: 1 | J33: Booking.com | K33: INR | L33: 38486 | M33: =IF(L33="","",IFERROR(L33*INDEX(Trip!$E$5:$E$14,MATCH(K33,Trip!$D$5:$D$14,0))/INDEX(Trip!$E$5:$E$14,MATCH(Trip!$B$10,Trip!$D$5:$D$14,0)),"")) -> 408.12301 | N33: =IF(OR(M33="",D33=""),"",M33/D33) -> 408.12301 | O33: =IF(M33="","",M33*I33) -> 408.12301 | P33: 46317 | Q33: =IF(ISNUMBER(P33),P33-TODAY(),IF(P33="","",P33)) -> 15 | R33: Quote | V33: =IF(M33="","",M33*(1+IF(U33="",Trip!$B$11,U33))) -> 469.34146 | W33: =IF(V33="","",V33*I33) -> 469.34146 | X33: =IF(OR(M33="",R33="Unavailable"),"",IF(M33=_xlfn.MINIFS($M$5:$M$604,$E$5:$E$604,E33,$G$5:$G$604,G33,$H$5:$H$604,H33,$R$5:$R$604,"<>Unavailable"),"⭐ Cheapest","")) | Y33: =IF(COUNTIFS($E$5:$E$604,E33,$G$5:$G$604,G33,$J$5:$J$604,"Booking.com")=0,"",_xlfn.MINIFS($M$5:$M$604,$E$5:$E$604,E33,$G$5:$G$604,G33,$J$5:$J$604,"Booking.com")) -> 368.8017 | Z33: =IF(OR(Y33="",M33="",J33="Booking.com"),"",Y33-M33)
A34: 30 | B34: Kandy | C34: 46378 | D34: 1 | E34: Taru Villas | G34: Deluxe Room DBL/SGL 27sqm | H34: HB | I34: 1 | J34: Ottila | K34: INR | L34: 33071 | M34: =IF(L34="","",IFERROR(L34*INDEX(Trip!$E$5:$E$14,MATCH(K34,Trip!$D$5:$D$14,0))/INDEX(Trip!$E$5:$E$14,MATCH(Trip!$B$10,Trip!$D$5:$D$14,0)),"")) -> 350.69989 | N34: =IF(OR(M34="",D34=""),"",M34/D34) -> 350.69989 | O34: =IF(M34="","",M34*I34) -> 350.69989 | P34: 46314 | Q34: =IF(ISNUMBER(P34),P34-TODAY(),IF(P34="","",P34)) -> 12 | R34: Blocked | S34: 101-26161087/1 | U34: 0.1149 | V34: =IF(M34="","",M34*(1+IF(U34="",Trip!$B$11,U34))) -> 390.99531 | W34: =IF(V34="","",V34*I34) -> 390.99531 | X34: =IF(OR(M34="",R34="Unavailable"),"",IF(M34=_xlfn.MINIFS($M$5:$M$604,$E$5:$E$604,E34,$G$5:$G$604,G34,$H$5:$H$604,H34,$R$5:$R$604,"<>Unavailable"),"⭐ Cheapest","")) -> ⭐ Cheapest | Y34: =IF(COUNTIFS($E$5:$E$604,E34,$G$5:$G$604,G34,$J$5:$J$604,"Booking.com")=0,"",_xlfn.MINIFS($M$5:$M$604,$E$5:$E$604,E34,$G$5:$G$604,G34,$J$5:$J$604,"Booking.com")) -> 368.8017 | Z34: =IF(OR(Y34="",M34="",J34="Booking.com"),"",Y34-M34) -> 18.101803 | AD34: 2 room on this price
A35: 31 | B35: Kandy | C35: 46378 | D35: 1 | E35: Taru Villas | G35: Deluxe Room DBL/SGL 27sqm | H35: HB | I35: 1 | J35: Booking.com | K35: INR | L35: 34778 | M35: =IF(L35="","",IFERROR(L35*INDEX(Trip!$E$5:$E$14,MATCH(K35,Trip!$D$5:$D$14,0))/INDEX(Trip!$E$5:$E$14,MATCH(Trip!$B$10,Trip!$D$5:$D$14,0)),"")) -> 368.8017 | N35: =IF(OR(M35="",D35=""),"",M35/D35) -> 368.8017 | O35: =IF(M35="","",M35*I35) -> 368.8017 | P35: 46317 | Q35: =IF(ISNUMBER(P35),P35-TODAY(),IF(P35="","",P35)) -> 15 | R35: Quote | V35: =IF(M35="","",M35*(1+IF(U35="",Trip!$B$11,U35))) -> 424.12195 | W35: =IF(V35="","",V35*I35) -> 424.12195 | X35: =IF(OR(M35="",R35="Unavailable"),"",IF(M35=_xlfn.MINIFS($M$5:$M$604,$E$5:$E$604,E35,$G$5:$G$604,G35,$H$5:$H$604,H35,$R$5:$R$604,"<>Unavailable"),"⭐ Cheapest","")) | Y35: =IF(COUNTIFS($E$5:$E$604,E35,$G$5:$G$604,G35,$J$5:$J$604,"Booking.com")=0,"",_xlfn.MINIFS($M$5:$M$604,$E$5:$E$604,E35,$G$5:$G$604,G35,$J$5:$J$604,"Booking.com")) -> 368.8017 | Z35: =IF(OR(Y35="",M35="",J35="Booking.com"),"",Y35-M35)
A36: 32 | B36: Kandy | C36: 46378 | D36: 1 | E36: Taru Villas | G36: Superior Double Room SGL 27sqm | H36: HB | I36: 1 | J36: Ottila | K36: INR | L36: 34480 | M36: =IF(L36="","",IFERROR(L36*INDEX(Trip!$E$5:$E$14,MATCH(K36,Trip!$D$5:$D$14,0))/INDEX(Trip!$E$5:$E$14,MATCH(Trip!$B$10,Trip!$D$5:$D$14,0)),"")) -> 365.64157 | N36: =IF(OR(M36="",D36=""),"",M36/D36) -> 365.64157 | O36: =IF(M36="","",M36*I36) -> 365.64157 | P36: 46314 | Q36: =IF(ISNUMBER(P36),P36-TODAY(),IF(P36="","",P36)) -> 12 | R36: Blocked | S36: 101-26161095/1 | V36: =IF(M36="","",M36*(1+IF(U36="",Trip!$B$11,U36))) -> 420.4878 | W36: =IF(V36="","",V36*I36) -> 420.4878 | X36: =IF(OR(M36="",R36="Unavailable"),"",IF(M36=_xlfn.MINIFS($M$5:$M$604,$E$5:$E$604,E36,$G$5:$G$604,G36,$H$5:$H$604,H36,$R$5:$R$604,"<>Unavailable"),"⭐ Cheapest","")) -> ⭐ Cheapest | Y36: =IF(COUNTIFS($E$5:$E$604,E36,$G$5:$G$604,G36,$J$5:$J$604,"Booking.com")=0,"",_xlfn.MINIFS($M$5:$M$604,$E$5:$E$604,E36,$G$5:$G$604,G36,$J$5:$J$604,"Booking.com")) | Z36: =IF(OR(Y36="",M36="",J36="Booking.com"),"",Y36-M36) | AD36: 1 room on this price
A37: 33 | B37: Kandy | C37: 46378 | D37: 1 | E37: Jetwing Kandy Gallery | G37: Luxury room DBL | H37: HB | I37: 1 | J37: Direct | K37: USD | L37: 315 | M37: =IF(L37="","",IFERROR(L37*INDEX(Trip!$E$5:$E$14,MATCH(K37,Trip!$D$5:$D$14,0))/INDEX(Trip!$E$5:$E$14,MATCH(Trip!$B$10,Trip!$D$5:$D$14,0)),"")) -> 315 | N37: =IF(OR(M37="",D37=""),"",M37/D37) -> 315 | O37: =IF(M37="","",M37*I37) -> 315 | P37: 46287 | Q37: =IF(ISNUMBER(P37),P37-TODAY(),IF(P37="","",P37)) -> -15 | R37: Blocked | U37: 0.0921 | V37: =IF(M37="","",M37*(1+IF(U37="",Trip!$B$11,U37))) -> 344.0115 | W37: =IF(V37="","",V37*I37) -> 344.0115 | X37: =IF(OR(M37="",R37="Unavailable"),"",IF(M37=_xlfn.MINIFS($M$5:$M$604,$E$5:$E$604,E37,$G$5:$G$604,G37,$H$5:$H$604,H37,$R$5:$R$604,"<>Unavailable"),"⭐ Cheapest","")) -> ⭐ Cheapest | Y37: =IF(COUNTIFS($E$5:$E$604,E37,$G$5:$G$604,G37,$J$5:$J$604,"Booking.com")=0,"",_xlfn.MINIFS($M$5:$M$604,$E$5:$E$604,E37,$G$5:$G$604,G37,$J$5:$J$604,"Booking.com")) | Z37: =IF(OR(Y37="",M37="",J37="Booking.com"),"",Y37-M37) | AA37: Y | AC37: Y
A38: 34 | B38: Kandy | C38: 46378 | D38: 1 | E38: Jetwing Kandy Gallery | G38: Luxury room SGL | H38: HB | I38: 1 | J38: Direct | K38: USD | L38: 265 | M38: =IF(L38="","",IFERROR(L38*INDEX(Trip!$E$5:$E$14,MATCH(K38,Trip!$D$5:$D$14,0))/INDEX(Trip!$E$5:$E$14,MATCH(Trip!$B$10,Trip!$D$5:$D$14,0)),"")) -> 265 | N38: =IF(OR(M38="",D38=""),"",M38/D38) -> 265 | O38: =IF(M38="","",M38*I38) -> 265 | P38: 46287 | Q38: =IF(ISNUMBER(P38),P38-TODAY(),IF(P38="","",P38)) -> -15 | R38: Blocked | U38: 0.1396 | V38: =IF(M38="","",M38*(1+IF(U38="",Trip!$B$11,U38))) -> 301.994 | W38: =IF(V38="","",V38*I38) -> 301.994 | X38: =IF(OR(M38="",R38="Unavailable"),"",IF(M38=_xlfn.MINIFS($M$5:$M$604,$E$5:$E$604,E38,$G$5:$G$604,G38,$H$5:$H$604,H38,$R$5:$R$604,"<>Unavailable"),"⭐ Cheapest","")) -> ⭐ Cheapest | Y38: =IF(COUNTIFS($E$5:$E$604,E38,$G$5:$G$604,G38,$J$5:$J$604,"Booking.com")=0,"",_xlfn.MINIFS($M$5:$M$604,$E$5:$E$604,E38,$G$5:$G$604,G38,$J$5:$J$604,"Booking.com")) | Z38: =IF(OR(Y38="",M38="",J38="Booking.com"),"",Y38-M38) | AB38: Y
A39: 35 | B39: Kandy | C39: 46378 | D39: 1 | E39: Jetwing Kandy Gallery | G39: Deluxe Room DBL/SGL 27sqm | H39: HB | I39: 1 | J39: Direct | K39: USD | L39: 409 | M39: =IF(L39="","",IFERROR(L39*INDEX(Trip!$E$5:$E$14,MATCH(K39,Trip!$D$5:$D$14,0))/INDEX(Trip!$E$5:$E$14,MATCH(Trip!$B$10,Trip!$D$5:$D$14,0)),"")) -> 409 | N39: =IF(OR(M39="",D39=""),"",M39/D39) -> 409 | O39: =IF(M39="","",M39*I39) -> 409 | P39: NRF | Q39: =IF(ISNUMBER(P39),P39-TODAY(),IF(P39="","",P39)) -> NRF | R39: Quote | V39: =IF(M39="","",M39*(1+IF(U39="",Trip!$B$11,U39))) -> 470.35 | W39: =IF(V39="","",V39*I39) -> 470.35 | X39: =IF(OR(M39="",R39="Unavailable"),"",IF(M39=_xlfn.MINIFS($M$5:$M$604,$E$5:$E$604,E39,$G$5:$G$604,G39,$H$5:$H$604,H39,$R$5:$R$604,"<>Unavailable"),"⭐ Cheapest","")) -> ⭐ Cheapest | Y39: =IF(COUNTIFS($E$5:$E$604,E39,$G$5:$G$604,G39,$J$5:$J$604,"Booking.com")=0,"",_xlfn.MINIFS($M$5:$M$604,$E$5:$E$604,E39,$G$5:$G$604,G39,$J$5:$J$604,"Booking.com")) | Z39: =IF(OR(Y39="",M39="",J39="Booking.com"),"",Y39-M39)
A40: 36 | B40: Kandy | C40: 46378 | D40: 1 | E40: Taru Villas Levita | F40: 5 | G40: Superior room 35M2 DBL/SGL | H40: BB | I40: 1 | J40: TBO | K40: INR | L40: 30414 | M40: =IF(L40="","",IFERROR(L40*INDEX(Trip!$E$5:$E$14,MATCH(K40,Trip!$D$5:$D$14,0))/INDEX(Trip!$E$5:$E$14,MATCH(Trip!$B$10,Trip!$D$5:$D$14,0)),"")) -> 322.52386 | N40: =IF(OR(M40="",D40=""),"",M40/D40) -> 322.52386 | O40: =IF(M40="","",M40*I40) -> 322.52386 | P40: 46345 | Q40: =IF(ISNUMBER(P40),P40-TODAY(),IF(P40="","",P40)) -> 43 | R40: Quote | V40: =IF(M40="","",M40*(1+IF(U40="",Trip!$B$11,U40))) -> 370.90244 | W40: =IF(V40="","",V40*I40) -> 370.90244 | X40: =IF(OR(M40="",R40="Unavailable"),"",IF(M40=_xlfn.MINIFS($M$5:$M$604,$E$5:$E$604,E40,$G$5:$G$604,G40,$H$5:$H$604,H40,$R$5:$R$604,"<>Unavailable"),"⭐ Cheapest","")) -> ⭐ Cheapest | Y40: =IF(COUNTIFS($E$5:$E$604,E40,$G$5:$G$604,G40,$J$5:$J$604,"Booking.com")=0,"",_xlfn.MINIFS($M$5:$M$604,$E$5:$E$604,E40,$G$5:$G$604,G40,$J$5:$J$604,"Booking.com")) -> 375.88547 | Z40: =IF(OR(Y40="",M40="",J40="Booking.com"),"",Y40-M40) -> 53.361612
...

Sheet Compare
A1: Price comparison — cost per room for the whole stay (costing currency)
A2: Built from the Quotes tab. Green = cheapest. Add a row here (copy the one above) if you add a new hotel/room on Quotes.
A4: City | B4: Hotel | C4: Room type | D4: Meal | E4: Ottila | F4: TBO | G4: BTR | H4: Helanka | I4: Direct | J4: Hotel website | K4: Booking.com | L4: Best price | M4: Best source | N4: Booking.com vs best
A5: Negombo | B5: Regal Reseau Hotel And Spa | C5: Super, Deluxe, King Bed, Sea View 28m2 | D5: BB | E5: =IF(COUNTIFS(Quotes!$E$5:$E$604,$B5,Quotes!$G$5:$G$604,$C5,Quotes!$H$5:$H$604,$D5,Quotes!$J$5:$J$604,E$4,Quotes!$R$5:$R$604,"<>Unavailable")=0,"",_xlfn.MINIFS(Quotes!$M$5:$M$604,Quotes!$E$5:$E$604,$B5,Quotes!$G$5:$G$604,$C5,Quotes!$H$5:$H$604,$D5,Quotes!$J$5:$J$604,E$4,Quotes!$R$5:$R$604,"<>Unavailable")) -> 150.7211 | F5: =IF(COUNTIFS(Quotes!$E$5:$E$604,$B5,Quotes!$G$5:$G$604,$C5,Quotes!$H$5:$H$604,$D5,Quotes!$J$5:$J$604,F$4,Quotes!$R$5:$R$604,"<>Unavailable")=0,"",_xlfn.MINIFS(Quotes!$M$5:$M$604,Quotes!$E$5:$E$604,$B5,Quotes!$G$5:$G$604,$C5,Quotes!$H$5:$H$604,$D5,Quotes!$J$5:$J$604,F$4,Quotes!$R$5:$R$604,"<>Unavailable")) | G5: =IF(COUNTIFS(Quotes!$E$5:$E$604,$B5,Quotes!$G$5:$G$604,$C5,Quotes!$H$5:$H$604,$D5,Quotes!$J$5:$J$604,G$4,Quotes!$R$5:$R$604,"<>Unavailable")=0,"",_xlfn.MINIFS(Quotes!$M$5:$M$604,Quotes!$E$5:$E$604,$B5,Quotes!$G$5:$G$604,$C5,Quotes!$H$5:$H$604,$D5,Quotes!$J$5:$J$604,G$4,Quotes!$R$5:$R$604,"<>Unavailable")) | H5: =IF(COUNTIFS(Quotes!$E$5:$E$604,$B5,Quotes!$G$5:$G$604,$C5,Quotes!$H$5:$H$604,$D5,Quotes!$J$5:$J$604,H$4,Quotes!$R$5:$R$604,"<>Unavailable")=0,"",_xlfn.MINIFS(Quotes!$M$5:$M$604,Quotes!$E$5:$E$604,$B5,Quotes!$G$5:$G$604,$C5,Quotes!$H$5:$H$604,$D5,Quotes!$J$5:$J$604,H$4,Quotes!$R$5:$R$604,"<>Unavailable")) | I5: =IF(COUNTIFS(Quotes!$E$5:$E$604,$B5,Quotes!$G$5:$G$604,$C5,Quotes!$H$5:$H$604,$D5,Quotes!$J$5:$J$604,I$4,Quotes!$R$5:$R$604,"<>Unavailable")=0,"",_xlfn.MINIFS(Quotes!$M$5:$M$604,Quotes!$E$5:$E$604,$B5,Quotes!$G$5:$G$604,$C5,Quotes!$H$5:$H$604,$D5,Quotes!$J$5:$J$604,I$4,Quotes!$R$5:$R$604,"<>Unavailable")) | J5: =IF(COUNTIFS(Quotes!$E$5:$E$604,$B5,Quotes!$G$5:$G$604,$C5,Quotes!$H$5:$H$604,$D5,Quotes!$J$5:$J$604,J$4,Quotes!$R$5:$R$604,"<>Unavailable")=0,"",_xlfn.MINIFS(Quotes!$M$5:$M$604,Quotes!$E$5:$E$604,$B5,Quotes!$G$5:$G$604,$C5,Quotes!$H$5:$H$604,$D5,Quotes!$J$5:$J$604,J$4,Quotes!$R$5:$R$604,"<>Unavailable")) | K5: =IF(COUNTIFS(Quotes!$E$5:$E$604,$B5,Quotes!$G$5:$G$604,$C5,Quotes!$H$5:$H$604,$D5,Quotes!$J$5:$J$604,K$4,Quotes!$R$5:$R$604,"<>Unavailable")=0,"",_xlfn.MINIFS(Quotes!$M$5:$M$604,Quotes!$E$5:$E$604,$B5,Quotes!$G$5:$G$604,$C5,Quotes!$H$5:$H$604,$D5,Quotes!$J$5:$J$604,K$4,Quotes!$R$5:$R$604,"<>Unavailable")) -> 139.14104 | L5: =IF(COUNT(E5:K5)=0,"",MIN(E5:K5)) -> 139.14104 | M5: =IF(L5="","",INDEX($E$4:$K$4,MATCH(L5,E5:K5,0))) -> Booking.com | N5: =IF(OR(K5="",COUNT(E5:J5)=0),"",K5-MIN(E5:J5)) -> -11.580064
A6: Negombo | B6: Jetwing Sea Hotel | C6: Standard Double Sea View | D6: BB | E6: =IF(COUNTIFS(Quotes!$E$5:$E$604,$B6,Quotes!$G$5:$G$604,$C6,Quotes!$H$5:$H$604,$D6,Quotes!$J$5:$J$604,E$4,Quotes!$R$5:$R$604,"<>Unavailable")=0,"",_xlfn.MINIFS(Quotes!$M$5:$M$604,Quotes!$E$5:$E$604,$B6,Quotes!$G$5:$G$604,$C6,Quotes!$H$5:$H$604,$D6,Quotes!$J$5:$J$604,E$4,Quotes!$R$5:$R$604,"<>Unavailable")) -> 109.41676 | F6: =IF(COUNTIFS(Quotes!$E$5:$E$604,$B6,Quotes!$G$5:$G$604,$C6,Quotes!$H$5:$H$604,$D6,Quotes!$J$5:$J$604,F$4,Quotes!$R$5:$R$604,"<>Unavailable")=0,"",_xlfn.MINIFS(Quotes!$M$5:$M$604,Quotes!$E$5:$E$604,$B6,Quotes!$G$5:$G$604,$C6,Quotes!$H$5:$H$604,$D6,Quotes!$J$5:$J$604,F$4,Quotes!$R$5:$R$604,"<>Unavailable")) | G6: =IF(COUNTIFS(Quotes!$E$5:$E$604,$B6,Quotes!$G$5:$G$604,$C6,Quotes!$H$5:$H$604,$D6,Quotes!$J$5:$J$604,G$4,Quotes!$R$5:$R$604,"<>Unavailable")=0,"",_xlfn.MINIFS(Quotes!$M$5:$M$604,Quotes!$E$5:$E$604,$B6,Quotes!$G$5:$G$604,$C6,Quotes!$H$5:$H$604,$D6,Quotes!$J$5:$J$604,G$4,Quotes!$R$5:$R$604,"<>Unavailable")) | H6: =IF(COUNTIFS(Quotes!$E$5:$E$604,$B6,Quotes!$G$5:$G$604,$C6,Quotes!$H$5:$H$604,$D6,Quotes!$J$5:$J$604,H$4,Quotes!$R$5:$R$604,"<>Unavailable")=0,"",_xlfn.MINIFS(Quotes!$M$5:$M$604,Quotes!$E$5:$E$604,$B6,Quotes!$G$5:$G$604,$C6,Quotes!$H$5:$H$604,$D6,Quotes!$J$5:$J$604,H$4,Quotes!$R$5:$R$604,"<>Unavailable")) | I6: =IF(COUNTIFS(Quotes!$E$5:$E$604,$B6,Quotes!$G$5:$G$604,$C6,Quotes!$H$5:$H$604,$D6,Quotes!$J$5:$J$604,I$4,Quotes!$R$5:$R$604,"<>Unavailable")=0,"",_xlfn.MINIFS(Quotes!$M$5:$M$604,Quotes!$E$5:$E$604,$B6,Quotes!$G$5:$G$604,$C6,Quotes!$H$5:$H$604,$D6,Quotes!$J$5:$J$604,I$4,Quotes!$R$5:$R$604,"<>Unavailable")) | J6: =IF(COUNTIFS(Quotes!$E$5:$E$604,$B6,Quotes!$G$5:$G$604,$C6,Quotes!$H$5:$H$604,$D6,Quotes!$J$5:$J$604,J$4,Quotes!$R$5:$R$604,"<>Unavailable")=0,"",_xlfn.MINIFS(Quotes!$M$5:$M$604,Quotes!$E$5:$E$604,$B6,Quotes!$G$5:$G$604,$C6,Quotes!$H$5:$H$604,$D6,Quotes!$J$5:$J$604,J$4,Quotes!$R$5:$R$604,"<>Unavailable")) | K6: =IF(COUNTIFS(Quotes!$E$5:$E$604,$B6,Quotes!$G$5:$G$604,$C6,Quotes!$H$5:$H$604,$D6,Quotes!$J$5:$J$604,K$4,Quotes!$R$5:$R$604,"<>Unavailable")=0,"",_xlfn.MINIFS(Quotes!$M$5:$M$604,Quotes!$E$5:$E$604,$B6,Quotes!$G$5:$G$604,$C6,Quotes!$H$5:$H$604,$D6,Quotes!$J$5:$J$604,K$4,Quotes!$R$5:$R$604,"<>Unavailable")) | L6: =IF(COUNT(E6:K6)=0,"",MIN(E6:K6)) -> 109.41676 | M6: =IF(L6="","",INDEX($E$4:$K$4,MATCH(L6,E6:K6,0))) -> Ottila | N6: =IF(OR(K6="",COUNT(E6:J6)=0),"",K6-MIN(E6:J6))
A7: Negombo | B7: Jetwing Blue | C7: Deluxe Room | D7: BB | E7: =IF(COUNTIFS(Quotes!$E$5:$E$604,$B7,Quotes!$G$5:$G$604,$C7,Quotes!$H$5:$H$604,$D7,Quotes!$J$5:$J$604,E$4,Quotes!$R$5:$R$604,"<>Unavailable")=0,"",_xlfn.MINIFS(Quotes!$M$5:$M$604,Quotes!$E$5:$E$604,$B7,Quotes!$G$5:$G$604,$C7,Quotes!$H$5:$H$604,$D7,Quotes!$J$5:$J$604,E$4,Quotes!$R$5:$R$604,"<>Unavailable")) -> 160.74231 | F7: =IF(COUNTIFS(Quotes!$E$5:$E$604,$B7,Quotes!$G$5:$G$604,$C7,Quotes!$H$5:$H$604,$D7,Quotes!$J$5:$J$604,F$4,Quotes!$R$5:$R$604,"<>Unavailable")=0,"",_xlfn.MINIFS(Quotes!$M$5:$M$604,Quotes!$E$5:$E$604,$B7,Quotes!$G$5:$G$604,$C7,Quotes!$H$5:$H$604,$D7,Quotes!$J$5:$J$604,F$4,Quotes!$R$5:$R$604,"<>Unavailable")) | G7: =IF(COUNTIFS(Quotes!$E$5:$E$604,$B7,Quotes!$G$5:$G$604,$C7,Quotes!$H$5:$H$604,$D7,Quotes!$J$5:$J$604,G$4,Quotes!$R$5:$R$604,"<>Unavailable")=0,"",_xlfn.MINIFS(Quotes!$M$5:$M$604,Quotes!$E$5:$E$604,$B7,Quotes!$G$5:$G$604,$C7,Quotes!$H$5:$H$604,$D7,Quotes!$J$5:$J$604,G$4,Quotes!$R$5:$R$604,"<>Unavailable")) | H7: =IF(COUNTIFS(Quotes!$E$5:$E$604,$B7,Quotes!$G$5:$G$604,$C7,Quotes!$H$5:$H$604,$D7,Quotes!$J$5:$J$604,H$4,Quotes!$R$5:$R$604,"<>Unavailable")=0,"",_xlfn.MINIFS(Quotes!$M$5:$M$604,Quotes!$E$5:$E$604,$B7,Quotes!$G$5:$G$604,$C7,Quotes!$H$5:$H$604,$D7,Quotes!$J$5:$J$604,H$4,Quotes!$R$5:$R$604,"<>Unavailable")) | I7: =IF(COUNTIFS(Quotes!$E$5:$E$604,$B7,Quotes!$G$5:$G$604,$C7,Quotes!$H$5:$H$604,$D7,Quotes!$J$5:$J$604,I$4,Quotes!$R$5:$R$604,"<>Unavailable")=0,"",_xlfn.MINIFS(Quotes!$M$5:$M$604,Quotes!$E$5:$E$604,$B7,Quotes!$G$5:$G$604,$C7,Quotes!$H$5:$H$604,$D7,Quotes!$J$5:$J$604,I$4,Quotes!$R$5:$R$604,"<>Unavailable")) | J7: =IF(COUNTIFS(Quotes!$E$5:$E$604,$B7,Quotes!$G$5:$G$604,$C7,Quotes!$H$5:$H$604,$D7,Quotes!$J$5:$J$604,J$4,Quotes!$R$5:$R$604,"<>Unavailable")=0,"",_xlfn.MINIFS(Quotes!$M$5:$M$604,Quotes!$E$5:$E$604,$B7,Quotes!$G$5:$G$604,$C7,Quotes!$H$5:$H$604,$D7,Quotes!$J$5:$J$604,J$4,Quotes!$R$5:$R$604,"<>Unavailable")) | K7: =IF(COUNTIFS(Quotes!$E$5:$E$604,$B7,Quotes!$G$5:$G$604,$C7,Quotes!$H$5:$H$604,$D7,Quotes!$J$5:$J$604,K$4,Quotes!$R$5:$R$604,"<>Unavailable")=0,"",_xlfn.MINIFS(Quotes!$M$5:$M$604,Quotes!$E$5:$E$604,$B7,Quotes!$G$5:$G$604,$C7,Quotes!$H$5:$H$604,$D7,Quotes!$J$5:$J$604,K$4,Quotes!$R$5:$R$604,"<>Unavailable")) -> 179 | L7: =IF(COUNT(E7:K7)=0,"",MIN(E7:K7)) -> 160.74231 | M7: =IF(L7="","",INDEX($E$4:$K$4,MATCH(L7,E7:K7,0))) -> Ottila | N7: =IF(OR(K7="",COUNT(E7:J7)=0),"",K7-MIN(E7:J7)) -> 18.257688
A8: Negombo | B8: The Wallawwa | C8: Walawwa Bedrom (1 King Bed) 35sqmr | D8: BB | E8: =IF(COUNTIFS(Quotes!$E$5:$E$604,$B8,Quotes!$G$5:$G$604,$C8,Quotes!$H$5:$H$604,$D8,Quotes!$J$5:$J$604,E$4,Quotes!$R$5:$R$604,"<>Unavailable")=0,"",_xlfn.MINIFS(Quotes!$M$5:$M$604,Quotes!$E$5:$E$604,$B8,Quotes!$G$5:$G$604,$C8,Quotes!$H$5:$H$604,$D8,Quotes!$J$5:$J$604,E$4,Quotes!$R$5:$R$604,"<>Unavailable")) -> 533.18134 | F8: =IF(COUNTIFS(Quotes!$E$5:$E$604,$B8,Quotes!$G$5:$G$604,$C8,Quotes!$H$5:$H$604,$D8,Quotes!$J$5:$J$604,F$4,Quotes!$R$5:$R$604,"<>Unavailable")=0,"",_xlfn.MINIFS(Quotes!$M$5:$M$604,Quotes!$E$5:$E$604,$B8,Quotes!$G$5:$G$604,$C8,Quotes!$H$5:$H$604,$D8,Quotes!$J$5:$J$604,F$4,Quotes!$R$5:$R$604,"<>Unavailable")) | G8: =IF(COUNTIFS(Quotes!$E$5:$E$604,$B8,Quotes!$G$5:$G$604,$C8,Quotes!$H$5:$H$604,$D8,Quotes!$J$5:$J$604,G$4,Quotes!$R$5:$R$604,"<>Unavailable")=0,"",_xlfn.MINIFS(Quotes!$M$5:$M$604,Quotes!$E$5:$E$604,$B8,Quotes!$G$5:$G$604,$C8,Quotes!$H$5:$H$604,$D8,Quotes!$J$5:$J$604,G$4,Quotes!$R$5:$R$604,"<>Unavailable")) | H8: =IF(COUNTIFS(Quotes!$E$5:$E$604,$B8,Quotes!$G$5:$G$604,$C8,Quotes!$H$5:$H$604,$D8,Quotes!$J$5:$J$604,H$4,Quotes!$R$5:$R$604,"<>Unavailable")=0,"",_xlfn.MINIFS(Quotes!$M$5:$M$604,Quotes!$E$5:$E$604,$B8,Quotes!$G$5:$G$604,$C8,Quotes!$H$5:$H$604,$D8,Quotes!$J$5:$J$604,H$4,Quotes!$R$5:$R$604,"<>Unavailable")) | I8: =IF(COUNTIFS(Quotes!$E$5:$E$604,$B8,Quotes!$G$5:$G$604,$C8,Quotes!$H$5:$H$604,$D8,Quotes!$J$5:$J$604,I$4,Quotes!$R$5:$R$604,"<>Unavailable")=0,"",_xlfn.MINIFS(Quotes!$M$5:$M$604,Quotes!$E$5:$E$604,$B8,Quotes!$G$5:$G$604,$C8,Quotes!$H$5:$H$604,$D8,Quotes!$J$5:$J$604,I$4,Quotes!$R$5:$R$604,"<>Unavailable")) | J8: =IF(COUNTIFS(Quotes!$E$5:$E$604,$B8,Quotes!$G$5:$G$604,$C8,Quotes!$H$5:$H$604,$D8,Quotes!$J$5:$J$604,J$4,Quotes!$R$5:$R$604,"<>Unavailable")=0,"",_xlfn.MINIFS(Quotes!$M$5:$M$604,Quotes!$E$5:$E$604,$B8,Quotes!$G$5:$G$604,$C8,Quotes!$H$5:$H$604,$D8,Quotes!$J$5:$J$604,J$4,Quotes!$R$5:$R$604,"<>Unavailable")) | K8: =IF(COUNTIFS(Quotes!$E$5:$E$604,$B8,Quotes!$G$5:$G$604,$C8,Quotes!$H$5:$H$604,$D8,Quotes!$J$5:$J$604,K$4,Quotes!$R$5:$R$604,"<>Unavailable")=0,"",_xlfn.MINIFS(Quotes!$M$5:$M$604,Quotes!$E$5:$E$604,$B8,Quotes!$G$5:$G$604,$C8,Quotes!$H$5:$H$604,$D8,Quotes!$J$5:$J$604,K$4,Quotes!$R$5:$R$604,"<>Unavailable")) -> 580 | L8: =IF(COUNT(E8:K8)=0,"",MIN(E8:K8)) -> 533.18134 | M8: =IF(L8="","",INDEX($E$4:$K$4,MATCH(L8,E8:K8,0))) -> Ottila | N8: =IF(OR(K8="",COUNT(E8:J8)=0),"",K8-MIN(E8:J8)) -> 46.818664
A9: Negombo | B9: Wattura Resort And Spa | C9: Suite With River View (1 King Bed) 72sqmt | D9: BB | E9: =IF(COUNTIFS(Quotes!$E$5:$E$604,$B9,Quotes!$G$5:$G$604,$C9,Quotes!$H$5:$H$604,$D9,Quotes!$J$5:$J$604,E$4,Quotes!$R$5:$R$604,"<>Unavailable")=0,"",_xlfn.MINIFS(Quotes!$M$5:$M$604,Quotes!$E$5:$E$604,$B9,Quotes!$G$5:$G$604,$C9,Quotes!$H$5:$H$604,$D9,Quotes!$J$5:$J$604,E$4,Quotes!$R$5:$R$604,"<>Unavailable")) -> 236.38388 | F9: =IF(COUNTIFS(Quotes!$E$5:$E$604,$B9,Quotes!$G$5:$G$604,$C9,Quotes!$H$5:$H$604,$D9,Quotes!$J$5:$J$604,F$4,Quotes!$R$5:$R$604,"<>Unavailable")=0,"",_xlfn.MINIFS(Quotes!$M$5:$M$604,Quotes!$E$5:$E$604,$B9,Quotes!$G$5:$G$604,$C9,Quotes!$H$5:$H$604,$D9,Quotes!$J$5:$J$604,F$4,Quotes!$R$5:$R$604,"<>Unavailable")) | G9: =IF(COUNTIFS(Quotes!$E$5:$E$604,$B9,Quotes!$G$5:$G$604,$C9,Quotes!$H$5:$H$604,$D9,Quotes!$J$5:$J$604,G$4,Quotes!$R$5:$R$604,"<>Unavailable")=0,"",_xlfn.MINIFS(Quotes!$M$5:$M$604,Quotes!$E$5:$E$604,$B9,Quotes!$G$5:$G$604,$C9,Quotes!$H$5:$H$604,$D9,Quotes!$J$5:$J$604,G$4,Quotes!$R$5:$R$604,"<>Unavailable")) | H9: =IF(COUNTIFS(Quotes!$E$5:$E$604,$B9,Quotes!$G$5:$G$604,$C9,Quotes!$H$5:$H$604,$D9,Quotes!$J$5:$J$604,H$4,Quotes!$R$5:$R$604,"<>Unavailable")=0,"",_xlfn.MINIFS(Quotes!$M$5:$M$604,Quotes!$E$5:$E$604,$B9,Quotes!$G$5:$G$604,$C9,Quotes!$H$5:$H$604,$D9,Quotes!$J$5:$J$604,H$4,Quotes!$R$5:$R$604,"<>Unavailable")) | I9: =IF(COUNTIFS(Quotes!$E$5:$E$604,$B9,Quotes!$G$5:$G$604,$C9,Quotes!$H$5:$H$604,$D9,Quotes!$J$5:$J$604,I$4,Quotes!$R$5:$R$604,"<>Unavailable")=0,"",_xlfn.MINIFS(Quotes!$M$5:$M$604,Quotes!$E$5:$E$604,$B9,Quotes!$G$5:$G$604,$C9,Quotes!$H$5:$H$604,$D9,Quotes!$J$5:$J$604,I$4,Quotes!$R$5:$R$604,"<>Unavailable")) | J9: =IF(COUNTIFS(Quotes!$E$5:$E$604,$B9,Quotes!$G$5:$G$604,$C9,Quotes!$H$5:$H$604,$D9,Quotes!$J$5:$J$604,J$4,Quotes!$R$5:$R$604,"<>Unavailable")=0,"",_xlfn.MINIFS(Quotes!$M$5:$M$604,Quotes!$E$5:$E$604,$B9,Quotes!$G$5:$G$604,$C9,Quotes!$H$5:$H$604,$D9,Quotes!$J$5:$J$604,J$4,Quotes!$R$5:$R$604,"<>Unavailable")) | K9: =IF(COUNTIFS(Quotes!$E$5:$E$604,$B9,Quotes!$G$5:$G$604,$C9,Quotes!$H$5:$H$604,$D9,Quotes!$J$5:$J$604,K$4,Quotes!$R$5:$R$604,"<>Unavailable")=0,"",_xlfn.MINIFS(Quotes!$M$5:$M$604,Quotes!$E$5:$E$604,$B9,Quotes!$G$5:$G$604,$C9,Quotes!$H$5:$H$604,$D9,Quotes!$J$5:$J$604,K$4,Quotes!$R$5:$R$604,"<>Unavailable")) -> 250 | L9: =IF(COUNT(E9:K9)=0,"",MIN(E9:K9)) -> 236.38388 | M9: =IF(L9="","",INDEX($E$4:$K$4,MATCH(L9,E9:K9,0))) -> Ottila | N9: =IF(OR(K9="",COUNT(E9:J9)=0),"",K9-MIN(E9:J9)) -> 13.616119
A10: Negombo | B10: Sentido Heritance Negombo | C10: Deluxe King 40sqmt | D10: BB | E10: =IF(COUNTIFS(Quotes!$E$5:$E$604,$B10,Quotes!$G$5:$G$604,$C10,Quotes!$H$5:$H$604,$D10,Quotes!$J$5:$J$604,E$4,Quotes!$R$5:$R$604,"<>Unavailable")=0,"",_xlfn.MINIFS(Quotes!$M$5:$M$604,Quotes!$E$5:$E$604,$B10,Quotes!$G$5:$G$604,$C10,Quotes!$H$5:$H$604,$D10,Quotes!$J$5:$J$604,E$4,Quotes!$R$5:$R$604,"<>Unavailable")) -> 182.27996 | F10: =IF(COUNTIFS(Quotes!$E$5:$E$604,$B10,Quotes!$G$5:$G$604,$C10,Quotes!$H$5:$H$604,$D10,Quotes!$J$5:$J$604,F$4,Quotes!$R$5:$R$604,"<>Unavailable")=0,"",_xlfn.MINIFS(Quotes!$M$5:$M$604,Quotes!$E$5:$E$604,$B10,Quotes!$G$5:$G$604,$C10,Quotes!$H$5:$H$604,$D10,Quotes!$J$5:$J$604,F$4,Quotes!$R$5:$R$604,"<>Unavailable")) | G10: =IF(COUNTIFS(Quotes!$E$5:$E$604,$B10,Quotes!$G$5:$G$604,$C10,Quotes!$H$5:$H$604,$D10,Quotes!$J$5:$J$604,G$4,Quotes!$R$5:$R$604,"<>Unavailable")=0,"",_xlfn.MINIFS(Quotes!$M$5:$M$604,Quotes!$E$5:$E$604,$B10,Quotes!$G$5:$G$604,$C10,Quotes!$H$5:$H$604,$D10,Quotes!$J$5:$J$604,G$4,Quotes!$R$5:$R$604,"<>Unavailable")) | H10: =IF(COUNTIFS(Quotes!$E$5:$E$604,$B10,Quotes!$G$5:$G$604,$C10,Quotes!$H$5:$H$604,$D10,Quotes!$J$5:$J$604,H$4,Quotes!$R$5:$R$604,"<>Unavailable")=0,"",_xlfn.MINIFS(Quotes!$M$5:$M$604,Quotes!$E$5:$E$604,$B10,Quotes!$G$5:$G$604,$C10,Quotes!$H$5:$H$604,$D10,Quotes!$J$5:$J$604,H$4,Quotes!$R$5:$R$604,"<>Unavailable")) | I10: =IF(COUNTIFS(Quotes!$E$5:$E$604,$B10,Quotes!$G$5:$G$604,$C10,Quotes!$H$5:$H$604,$D10,Quotes!$J$5:$J$604,I$4,Quotes!$R$5:$R$604,"<>Unavailable")=0,"",_xlfn.MINIFS(Quotes!$M$5:$M$604,Quotes!$E$5:$E$604,$B10,Quotes!$G$5:$G$604,$C10,Quotes!$H$5:$H$604,$D10,Quotes!$J$5:$J$604,I$4,Quotes!$R$5:$R$604,"<>Unavailable")) | J10: =IF(COUNTIFS(Quotes!$E$5:$E$604,$B10,Quotes!$G$5:$G$604,$C10,Quotes!$H$5:$H$604,$D10,Quotes!$J$5:$J$604,J$4,Quotes!$R$5:$R$604,"<>Unavailable")=0,"",_xlfn.MINIFS(Quotes!$M$5:$M$604,Quotes!$E$5:$E$604,$B10,Quotes!$G$5:$G$604,$C10,Quotes!$H$5:$H$604,$D10,Quotes!$J$5:$J$604,J$4,Quotes!$R$5:$R$604,"<>Unavailable")) | K10: =IF(COUNTIFS(Quotes!$E$5:$E$604,$B10,Quotes!$G$5:$G$604,$C10,Quotes!$H$5:$H$604,$D10,Quotes!$J$5:$J$604,K$4,Quotes!$R$5:$R$604,"<>Unavailable")=0,"",_xlfn.MINIFS(Quotes!$M$5:$M$604,Quotes!$E$5:$E$604,$B10,Quotes!$G$5:$G$604,$C10,Quotes!$H$5:$H$604,$D10,Quotes!$J$5:$J$604,K$4,Quotes!$R$5:$R$604,"<>Unavailable")) -> 329 | L10: =IF(COUNT(E10:K10)=0,"",MIN(E10:K10)) -> 182.27996 | M10: =IF(L10="","",INDEX($E$4:$K$4,MATCH(L10,E10:K10,0))) -> Ottila | N10: =IF(OR(K10="",COUNT(E10:J10)=0),"",K10-MIN(E10:J10)) -> 146.72004
A11: Negombo | B11: Jetwing Blue | C11: TWIN DELUXE SEA VIEW( 2 Adults ) 59sqmt | D11: BB | E11: =IF(COUNTIFS(Quotes!$E$5:$E$604,$B11,Quotes!$G$5:$G$604,$C11,Quotes!$H$5:$H$604,$D11,Quotes!$J$5:$J$604,E$4,Quotes!$R$5:$R$604,"<>Unavailable")=0,"",_xlfn.MINIFS(Quotes!$M$5:$M$604,Quotes!$E$5:$E$604,$B11,Quotes!$G$5:$G$604,$C11,Quotes!$H$5:$H$604,$D11,Quotes!$J$5:$J$604,E$4,Quotes!$R$5:$R$604,"<>Unavailable")) -> 170.20148 | F11: =IF(COUNTIFS(Quotes!$E$5:$E$604,$B11,Quotes!$G$5:$G$604,$C11,Quotes!$H$5:$H$604,$D11,Quotes!$J$5:$J$604,F$4,Quotes!$R$5:$R$604,"<>Unavailable")=0,"",_xlfn.MINIFS(Quotes!$M$5:$M$604,Quotes!$E$5:$E$604,$B11,Quotes!$G$5:$G$604,$C11,Quotes!$H$5:$H$604,$D11,Quotes!$J$5:$J$604,F$4,Quotes!$R$5:$R$604,"<>Unavailable")) | G11: =IF(COUNTIFS(Quotes!$E$5:$E$604,$B11,Quotes!$G$5:$G$604,$C11,Quotes!$H$5:$H$604,$D11,Quotes!$J$5:$J$604,G$4,Quotes!$R$5:$R$604,"<>Unavailable")=0,"",_xlfn.MINIFS(Quotes!$M$5:$M$604,Quotes!$E$5:$E$604,$B11,Quotes!$G$5:$G$604,$C11,Quotes!$H$5:$H$604,$D11,Quotes!$J$5:$J$604,G$4,Quotes!$R$5:$R$604,"<>Unavailable")) | H11: =IF(COUNTIFS(Quotes!$E$5:$E$604,$B11,Quotes!$G$5:$G$604,$C11,Quotes!$H$5:$H$604,$D11,Quotes!$J$5:$J$604,H$4,Quotes!$R$5:$R$604,"<>Unavailable")=0,"",_xlfn.MINIFS(Quotes!$M$5:$M$604,Quotes!$E$5:$E$604,$B11,Quotes!$G$5:$G$604,$C11,Quotes!$H$5:$H$604,$D11,Quotes!$J$5:$J$604,H$4,Quotes!$R$5:$R$604,"<>Unavailable")) | I11: =IF(COUNTIFS(Quotes!$E$5:$E$604,$B11,Quotes!$G$5:$G$604,$C11,Quotes!$H$5:$H$604,$D11,Quotes!$J$5:$J$604,I$4,Quotes!$R$5:$R$604,"<>Unavailable")=0,"",_xlfn.MINIFS(Quotes!$M$5:$M$604,Quotes!$E$5:$E$604,$B11,Quotes!$G$5:$G$604,$C11,Quotes!$H$5:$H$604,$D11,Quotes!$J$5:$J$604,I$4,Quotes!$R$5:$R$604,"<>Unavailable")) | J11: =IF(COUNTIFS(Quotes!$E$5:$E$604,$B11,Quotes!$G$5:$G$604,$C11,Quotes!$H$5:$H$604,$D11,Quotes!$J$5:$J$604,J$4,Quotes!$R$5:$R$604,"<>Unavailable")=0,"",_xlfn.MINIFS(Quotes!$M$5:$M$604,Quotes!$E$5:$E$604,$B11,Quotes!$G$5:$G$604,$C11,Quotes!$H$5:$H$604,$D11,Quotes!$J$5:$J$604,J$4,Quotes!$R$5:$R$604,"<>Unavailable")) | K11: =IF(COUNTIFS(Quotes!$E$5:$E$604,$B11,Quotes!$G$5:$G$604,$C11,Quotes!$H$5:$H$604,$D11,Quotes!$J$5:$J$604,K$4,Quotes!$R$5:$R$604,"<>Unavailable")=0,"",_xlfn.MINIFS(Quotes!$M$5:$M$604,Quotes!$E$5:$E$604,$B11,Quotes!$G$5:$G$604,$C11,Quotes!$H$5:$H$604,$D11,Quotes!$J$5:$J$604,K$4,Quotes!$R$5:$R$604,"<>Unavailable")) | L11: =IF(COUNT(E11:K11)=0,"",MIN(E11:K11)) -> 170.20148 | M11: =IF(L11="","",INDEX($E$4:$K$4,MATCH(L11,E11:K11,0))) -> Ottila | N11: =IF(OR(K11="",COUNT(E11:J11)=0),"",K11-MIN(E11:J11))
